Workbook

Sheet DATA
A1: Year/Study | B1: Jurisdiction | C1: Mathematics scale Average | D1: science scale Average | E1: reading scale Average | F1: status of parents (hisei) Average | G1: experience of being bullied Average | H1: access to money Average | I1: current support for learning at home Average | J1: index teacher support in mathematics lessons Average | K1: Class Period Mathematics Average | L1: Class Period Science Average | M1: Class Periods Language Average | N1: number of students Average | O1: student-teacher ratio Average | P1: teachers fully certified Average | Q1: sense of belonging to school Average | R1: parent attitudes toward mathematics Average | S1: economic. social and cultural status Average | T1: GINI INDICATOR | U1: region | V1: Gender gap (boys - girls) Mathematics | W1: Gender gap (boys - girls) Readings | X1: GDP | Y1: spending on education | Z1: Duration of FULL and PARTIAL school closures (in weeks)
A2: 2022 | B2: International Average (OECD) | C2: 472.35812 | D2: 484.64661 | E2: 475.58887 | F2: 53.700492 | G2: -0.2987384 | H2: 0.00089982505 | I2: -0.14067731 | J2: -0.034661332 | K2: 4.5655961 | L2: — | M2: — | N2: 166.24062 | O2: 13.252173 | P2: 0.83 | Q2: -0.018258519 | R2: -0.16411773 | S2: 0.0023584575 | T2: - | U2: - | V2: - | W2: - | X2: 48388.078 | Y2: 102611.92 | Z2: -
A3: 2022 | B3: Australia | C3: 487.08425 | D3: 507.00087 | E3: 498.05094 | F3: 59.293815 | G3: 0.037333864 | H3: — | I3: — | J3: 0.13025618 | K3: 4.4238076 | L3: — | M3: — | N3: 187 | O3: 13 | P3: 0.941 | Q3: -0.22670157 | R3: — | S3: 0.3793666 | T3: 0 | U3: Oceania | V3: -11.370732 | W3: -21.5 | X3: 55949.217 | Y3: 126020.06 | Z3: =_xlfn.XLOOKUP(B3,Feuil4!A:A,Feuil4!C:C) -> 44
A4: 2022 | B4: Austria | C4: 487.2675 | D4: 491.27096 | E4: 480.40585 | F4: 53.055445 | G4: -0.26404826 | H4: -0.023977471 | I4: — | J4: -0.39363787 | K4: 3.3233925 | L4: — | M4: — | N4: — | O4: 10.074838 | P4: 0.85 | Q4: 0.44498218 | R4: — | S4: 0.069067359 | T4: 30.9 | U4: Europe | V4: -19.055576 | W4: -20.3 | X4: 59537.54 | Y4: 154067.1 | Z4: =_xlfn.XLOOKUP(B4,Feuil4!A:A,Feuil4!C:C) -> 39
A5: 2022 | B5: Belgium | C5: 489.48682 | D5: 490.57835 | E5: 478.85267 | F5: 53.389594 | G5: -0.25310342 | I5: — | J5: -0.21179245 | K5: 4.2547463 | L5: — | M5: — | N5: 149 | O5: 9 | P5: 0.87 | Q5: 0.02185523 | S5: 0.082876334 | T5: 26.4 | U5: Europe | V5: -7.642561 | W5: -27.5 | X5: 59372.89 | Y5: 130344.48 | Z5: =_xlfn.XLOOKUP(B5,Feuil4!A:A,Feuil4!C:C) -> 27
A6: 2022 | B6: Canada | C6: 496.94789 | D6: 515.01668 | E6: 507.1329 | F6: 58.694252 | G6: -0.2521081 | H6: 0.03 | I6: — | J6: — | K6: 4 | L6: — | M6: — | N6: — | O6: — | P6: 0.92 | Q6: -0.16173455 | R6: — | S6: 0.38110208 | T6: 0 | U6: North America | V6: -12.325277 | W6: -24.3 | X6: 52789.675 | Y6: 121678.16 | Z6: =_xlfn.XLOOKUP(B6,Feuil4!A:A,Feuil4!C:C) -> 51
A7: 2022 | B7: Chile | C7: 411.69657 | D7: 443.5434 | E7: 447.97896 | F7: 44.127175 | G7: -0.22680295 | H7: — | I7: — | J7: 0.39686204 | K7: 7 | L7: — | M7: — | N7: 130.76257 | O7: 18.374937 | P7: — | Q7: -0.22015999 | R7: — | S7: -0.50864929 | T7: 43 | U7: South America | V7: -16.286793 | W7: -6.6 | X7: 28372.04 | Y7: 60626.794 | Z7: =_xlfn.XLOOKUP(B7,Feuil4!A:A,Feuil4!C:C) -> 77
A8: 2022 | B8: Colombia | C8: 382.69684 | D8: 411.12067 | E8: 408.66503 | F8: 41.000778 | G8: -0.20909318 | H8: — | I8: 0.045472068 | J8: 0.52 | K8: 4.7308984 | L8: — | M8: — | N8: 111.11063 | O8: 25.102589 | P8: 0.85 | Q8: -0.15690719 | R8: 0.18062387 | S8: -1.0651249 | T8: - | U8: South America | V8: -8.9431601 | W8: -11.6 | X8: 16903.794 | Y8: 37314.825 | Z8: =_xlfn.XLOOKUP(B8,Feuil4!A:A,Feuil4!C:C) -> 77
A9: 2022 | B9: Costa Rica | C9: 384.57604 | D9: 410.98662 | E9: 415.23308 | F9: — | G9: -0.25354312 | H9: -0.17 | I9: 0.20099544 | J9: 0.56441419 | K9: 5.2850632 | L9: — | M9: — | N9: 174 | O9: 17 | P9: 0.81 | Q9: -0.094153901 | R9: 0.01295743 | S9: — | T9: - | U9: North America | V9: -15.16378 | W9: -2.6 | X9: 22613.981 | Z9: =_xlfn.XLOOKUP(B9,Feuil4!A:A,Feuil4!C:C) -> 79
A10: 2022 | B10: Czech Republic | C10: 486.99921 | D10: 497.74205 | E10: 488.60367 | F10: 50.883136 | G10: -0.16584353 | H10: 0.089187121 | I10: — | J10: -0.49632304 | K10: 4.8302672 | L10: — | M10: — | N10: 99.05523 | O10: 13.241301 | P10: 0.87 | Q10: -0.27989479 | R10: — | S10: -0.10408607 | T10: 25.9 | U10: Europe | V10: -7.4238329 | W10: -29.1 | X10: 45707.471 | Y10: 100835.2 | Z10: =_xlfn.XLOOKUP(B10,Feuil4!A:A,Feuil4!C:C) -> 46
A11: 2022 | B11: Denmark | C11: 489.27388 | D11: 493.81571 | E11: 488.80099 | F11: 62.289548 | G11: -0.043775353 | H11: 0.094962435 | I11: — | J11: 0.0030886563 | K11: 5.6240252 | L11: — | M11: — | N11: 76 | O11: 12 | P11: — | Q11: 0.10918696 | R11: — | S11: 0.47607774 | T11: 29.3 | U11: Europe | V11: -11.670993 | W11: -20.7 | X11: 64672.226 | Y11: 130685.34 | Z11: =_xlfn.XLOOKUP(B11,Feuil4!A:A,Feuil4!C:C) -> 34
A12: 2022 | B12: Estonia | C12: 509.94695 | D12: 525.81178 | E12: 511.03033 | F12: 54.918361 | G12: -0.12847185 | H12: — | I12: — | J12: -0.19360039 | K12: 4.8833478 | L12: — | M12: — | N12: 71.225472 | O12: 11.916763 | P12: 0.77 | Q12: -0.13748266 | R12: — | S12: 0.15072519 | T12: 32.3 | U12: Europe | V12: -6.3189001 | W12: -26.7 | X12: 42380.968 | Z12: =_xlfn.XLOOKUP(B12,Feuil4!A:A,Feuil4!C:C) -> 26
A13: 2022 | B13: Finland | C13: 484.13923 | D13: 510.95885 | E13: 490.21768 | F13: 55.509857 | G13: -0.39438433 | H13: — | I13: — | J13: -0.0021322557 | K13: 4.176204 | L13: — | M13: — | N13: 115.79033 | O13: 10.902245 | P13: 0.88 | Q13: 0.10115776 | R13: — | S13: 0.25848284 | T13: 27.9 | U13: Europe | V13: 5.068162 | W13: -44.7 | X13: 55203.328 | Y13: 126777.01 | Z13: =_xlfn.XLOOKUP(B13,Feuil4!A:A,Feuil4!C:C) -> 33
A14: 2022 | B14: France | C14: 473.94442 | D14: 487.22528 | E14: 473.85216 | F14: 53.075124 | G14: -0.21940103 | H14: — | I14: — | J14: -0.26265549 | K14: 4.0397096 | L14: — | M14: — | N14: 295 | O14: 12 | P14: 0.81 | Q14: -0.026856754 | R14: — | S14: 0.00018538929 | T14: 31.2 | U14: Europe | V14: -9.7898731 | W14: -20.2 | X14: 50996.437 | Y14: 109584.32 | Z14: =_xlfn.XLOOKUP(B14,Feuil4!A:A,Feuil4!C:C) -> 12
A15: 2022 | B15: Germany | C15: 474.82645 | D15: 492.42673 | E15: 479.79402 | F15: 51.9 | G15: -0.20320797 | H15: — | I15: — | J15: -0.15 | K15: 4 | L15: — | M15: — | N15: 102 | O15: 14 | P15: 0.86 | Q15: 0.26987259 | S15: -0.13699002 | T15: 0 | U15: Europe | V15: -11.3715 | W15: -19.4 | X15: 58276.015 | Y15: 121061.54 | Z15: =_xlfn.XLOOKUP(B15,Feuil4!A:A,Feuil4!C:C) -> 38
A16: 2022 | B16: Greece | C16: 430.14632 | D16: 440.78606 | E16: 438.44063 | F16: 51.139758 | G16: -0.25695866 | H16: — | I16: — | J16: -0.39718982 | K16: 5.114054 | L16: — | M16: — | N16: 95.296987 | O16: 8,7022377807454 | P16: 0.88 | Q16: -0.059726516 | R16: — | S16: -0.15486959 | T16: 33.4 | U16: Europe | V16: -5.9097557 | W16: -25.4 | X16: 31485.887 | Y16: 71509.49 | Z16: =_xlfn.XLOOKUP(B16,Feuil4!A:A,Feuil4!C:C) -> 37
A17: 2022 | B17: Hungary | C17: 472.77612 | D17: 485.89016 | E17: 472.97473 | F17: 51.077932 | G17: -0.42076819 | H17: 0.10284559 | I17: — | J17: -0.22273788 | K17: 4.0257243 | L17: — | M17: — | N17: 135 | O17: 11 | P17: — | Q17: 0.13858812 | R17: — | S17: 0.0029782259 | T17: 0 | U17: Europe | V17: -14.857639 | W17: -16.9 | X17: 36765.035 | Y17: 78968.656 | Z17: =_xlfn.XLOOKUP(B17,Feuil4!A:A,Feuil4!C:C) -> 39
A18: 2022 | B18: Iceland | C18: 458.91401 | D18: 446.96711 | E18: 435.92299 | F18: 60.463246 | G18: -0.4474593 | H18: — | I18: — | J18: 0.17543632 | K18: 5.5966186 | L18: — | M18: — | N18: — | O18: 11 | P18: 0.66 | Q18: 0.16405404 | R18: — | S18: 0.37810512 | T18: 0 | U18: Europe | V18: -3.3994341 | W18: -35.5 | X18: 57967.284 | Y18: 149636.86 | Z18: =_xlfn.XLOOKUP(B18,Feuil4!A:A,Feuil4!C:C) -> 6
A19: 2022 | B19: Ireland | C19: 491.64828 | D19: 503.84554 | E19: 516.00998 | F19: 59.725078 | G19: -0.2951771 | H19: — | I19: — | J19: 0.070590127 | K19: 3.9201593 | L19: — | M19: — | N19: 128.95801 | O19: 12.412021 | P19: 0.9 | Q19: -0.13205507 | R19: -0.11719259 | S19: 0.33297914 | T19: 29.9 | U19: Europe | V19: -12.725275 | W19: -18.3 | X19: 105355.2 | Y19: 94167.038 | Z19: =_xlfn.XLOOKUP(B19,Feuil4!A:A,Feuil4!C:C) -> 26
A20: 2022 | B20: Israel | C20: 457.89667 | D20: 464.75183 | E20: 473.8327 | F20: 61.953582 | G20: — | H20: — | I20: — | J20: 0.09 | K20: 5.557043 | L20: — | M20: — | N20: 171.92069 | O20: 11 | P20: 0.83 | Q20: — | R20: — | S20: 0.279957 | T20: 0 | U20: Middle East | V20: -11.212683 | W20: -23.1 | X20: 43450.551 | Y20: 94352.822 | Z20: =_xlfn.XLOOKUP(B20,Feuil4!A:A,Feuil4!C:C) -> 33
A21: 2022 | B21: Italy | C21: 471.25948 | D21: 477.46337 | E21: 481.59828 | F21: 49.431774 | G21: -0.49066922 | H21: -0.14788419 | I21: — | J21: -0.16053229 | K21: 4.2584989 | L21: — | M21: — | N21: 192.86031 | O21: 8.0992772 | P21: 0.74 | Q21: -0.064720885 | R21: -0.16852488 | S21: -0.10021048 | T21: 33.7 | U21: Europe | V21: -21.06222 | W21: -19.1 | X21: 46373.516 | Y21: 105754.32 | Z21: =_xlfn.XLOOKUP(B21,Feuil4!A:A,Feuil4!C:C) -> 38
A22: 2022 | B22: Japan | C22: 535.57931 | D22: 546.63445 | E22: 515.85461 | F22: 53.927255 | G22: -0.72255862 | H22: — | I22: — | J22: 0.24059203 | K22: 4.9604933 | L22: — | M22: — | N22: 262.02852 | O22: 11.473479 | P22: 0.96 | Q22: 0.24595838 | R22: — | S22: -0.0068250227 | T22: 0 | U22: Asia | V22: -8.9132423 | W22: -16.6 | X22: 42139.987 | Y22: 101399.34 | Z22: =_xlfn.XLOOKUP(B22,Feuil4!A:A,Feuil4!C:C) -> 11
A23: 2022 | B23: Korea | C23: 527.3025 | D23: 527.82242 | E23: 515.41539 | F23: 57.819386 | G23: -0.91216039 | H23: — | I23: -0.66849943 | J23: 0.06581342 | K23: 4.2119973 | L23: — | M23: — | N23: 235.19499 | O23: 11.724467 | P23: 0.84 | Q23: 0.26251164 | R23: -0.4734752 | S23: 0.22438569 | T23: - | U23: Asia | V23: -5.0800171 | W23: -34.2 | X23: 46888.791 | Y23: 144484.99 | Z23: =_xlfn.XLOOKUP(B23,Feuil4!A:A,Feuil4!C:C) -> 39
A24: 2022 | B24: Latvia | C24: 483.15946 | D24: 493.84277 | E24: 474.56865 | F24: 52.225843 | G24: 0.05265305 | H24: — | I24: — | J24: -0.21561088 | K24: 6.0203956 | L24: — | M24: — | N24: 63 | O24: 11 | P24: — | Q24: -0.24537478 | R24: -0.58 | S24: -0.0094825237 | T24: 33.7 | U24: Europe | V24: -9.5042953 | W24: -27.6 | X24: 34257.982 | Y24: 68784.493 | Z24: =_xlfn.XLOOKUP(B24,Feuil4!A:A,Feuil4!C:C) -> 49
A25: 2022 | B25: Lithuania | C25: 475.14676 | D25: 484.46341 | E25: 471.83423 | F25: 54.7 | G25: -0.43428206 | H25: — | I25: — | J25: -0.18995203 | K25: 4.8032614 | L25: — | M25: — | N25: 100.27434 | O25: 11.686657 | P25: 0.92 | Q25: -0.023424187 | R25: — | S25: 0.052295067 | T25: 36.6 | U25: Europe | V25: -5.1497512 | W25: -30.8 | X25: 43184.994 | Y25: 72114.251 | Z25: =_xlfn.XLOOKUP(B25,Feuil4!A:A,Feuil4!C:C) -> 38
A26: 2022 | B26: Luxembourg | Z26: =_xlfn.XLOOKUP(B26,Feuil4!A:A,Feuil4!C:C) -> 15
A27: 2022 | B27: Mexico | C27: 395.02992 | D27: 409.8866 | E27: 415.35896 | F27: 42.558595 | G27: -0.43966064 | H27: — | I27: — | J27: 0.44158924 | K27: 4.0762894 | L27: — | M27: — | N27: 394.95157 | O27: 31.590666 | P27: 0.33 | Q27: -0.18321321 | R27: — | S27: -0.95243733 | T27: 43.5 | U27: North America | V27: -12.100664 | W27: -7.8 | X27: 19584.672 | Y27: 28903.027 | Z27: =_xlfn.XLOOKUP(B27,Feuil4!A:A,Feuil4!C:C) -> 71
A28: 2022 | B28: Netherlands | C28: 492.67564 | D28: 488.31684 | E28: 459.24291 | F28: 56.238313 | G28: -0.49713965 | H28: 0.12086071 | I28: — | J28: -0.36355179 | K28: 3.3344697 | L28: — | M28: — | N28: 218 | O28: 17 | P28: 0.82 | Q28: 0.10237876 | R28: — | S28: 0.25346078 | T28: 0 | U28: Europe | V28: -10.649586 | W28: -25.9 | X28: 63741.704 | Y28: 119584.16 | Z28: =_xlfn.XLOOKUP(B28,Feuil4!A:A,Feuil4!C:C) -> 31
A29: 2022 | B29: New Zealand | C29: 479.07419 | D29: 504.1293 | E29: 500.85301 | F29: 58.007255 | G29: 0.005457728 | H29: — | I29: — | J29: 0.082404015 | K29: 4.2760903 | L29: — | M29: — | N29: — | O29: 15 | P29: 0.84 | Q29: -0.28784463 | R29: — | S29: 0.2190636 | T29: 0 | U29: Oceania | V29: -10.371503 | W29: -25.9 | X29: 46990.18 | Y29: 82261.005 | Z29: =_xlfn.XLOOKUP(B29,Feuil4!A:A,Feuil4!C:C) -> 24
A30: 2022 | B30: Norway | C30: 468.44995 | D30: 478.22646 | E30: 476.52388 | F30: 62.286994 | G30: -0.28237696 | H30: 0.17 | I30: — | J30: -0.1696634 | K30: 4.3080961 | L30: — | M30: — | N30: — | O30: — | P30: — | Q30: 0.22577004 | R30: — | S30: 0.52149711 | T30: 26.9 | U30: Europe | V30: 0.6598466 | W30: -41.7 | X30: 80534.611 | Y30: 153335.4 | Z30: =_xlfn.XLOOKUP(B30,Feuil4!A:A,Feuil4!C:C) -> 29
A31: 2022 | B31: Poland | C31: 488.96005 | D31: 499.16436 | E31: 488.71363 | F31: 52.03407 | G31: -0.35296353 | H31: 0.15479597 | I31: — | J31: -0.68566624 | K31: 3.8103623 | L31: — | M31: — | N31: 144.35008 | O31: 10.371461 | P31: 0.88 | Q31: -0.31210982 | R31: — | S31: -0.10514069 | T31: 28.9 | U31: Europe | V31: -5.5164599 | W31: -28.6 | X31: 38125.191 | Y31: 87741.196 | Z31: =_xlfn.XLOOKUP(B31,Feuil4!A:A,Feuil4!C:C) -> 43
A32: 2022 | B32: Portugal | C32: 471.91052 | D32: 484.37346 | E32: 476.58861 | F32: 51.018858 | G32: -0.54735401 | H32: -0.29024495 | I32: — | J32: 0.32979578 | K32: 4.0053628 | L32: — | M32: — | N32: 218.36504 | O32: 10.403298 | P32: 0.8 | Q32: 0.084369594 | R32: 0.00033991305 | S32: -0.22635526 | T32: 36.3 | U32: Europe | V32: -10.649423 | W32: -20.9 | X32: 36037.958 | Y32: 98982.972 | Z32: =_xlfn.XLOOKUP(B32,Feuil4!A:A,Feuil4!C:C) -> 24
A33: 2022 | B33: Slovak Republic | C33: 463.99462 | D33: 462.26948 | E33: 446.86061 | F33: 47.569681 | G33: -0.29370873 | H33: — | I33: — | J33: -0.20992051 | K33: 4.7756185 | L33: — | M33: — | N33: 79.566724 | O33: 12.556962 | P33: 0.75 | Q33: -0.20072177 | R33: — | S33: -0.30299667 | T33: - | U33: Europe | V33: -1.3687563 | W33: -29.6 | X33: 33418.522 | Y33: 75299.806 | Z33: =_xlfn.XLOOKUP(B33,Feuil4!A:A,Feuil4!C:C) -> 38
A34: 2022 | B34: Slovenia | C34: 484.52901 | D34: 499.96488 | E34: 468.53601 | F34: 57.661959 | G34: -0.42900458 | H34: — | I34: — | J34: -0.41471932 | K34: 4.0456452 | L34: — | M34: — | N34: 149.91697 | O34: 10.664504 | P34: 0.86 | Q34: 0.038575906 | R34: — | S34: 0.22580826 | T34: 24.3 | U34: Europe | V34: 1.7013248 | W34: -43.7 | X34: 43804.816 | Y34: 102335.93 | Z34: =_xlfn.XLOOKUP(B34,Feuil4!A:A,Feuil4!C:C) -> 47
A35: 2022 | B35: Spain | C35: 473.14021 | D35: 484.53365 | E35: 474.30711 | F35: 51.033223 | G35: -0.37901147 | H35: -0.18675319 | I35: — | J35: 0.061526505 | K35: 4.2212222 | L35: — | M35: — | N35: 91.038372 | O35: 11.582414 | P35: 0.87 | Q35: 0.27253456 | R35: — | S35: -0.033199497 | T35: 33.6 | U35: Europe | V35: -10.148127 | W35: -25.3 | X35: 40591.759 | Y35: 93094.234 | Z35: =_xlfn.XLOOKUP(B35,Feuil4!A:A,Feuil4!C:C) -> 15
A36: 2022 | B36: Sweden | C36: 481.76607 | D36: 493.54932 | E36: 486.97516 | F36: 59.230088 | G36: -0.26768245 | H36: — | I36: — | J36: 0.18966554 | K36: 4.3408894 | L36: — | M36: — | N36: — | O36: 12 | P36: 0.81 | Q36: 0.088342878 | R36: — | S36: 0.32659102 | T36: 31.6 | U36: Europe | V36: -2.1699214 | W36: -36.7 | X36: 59222.634 | Y36: 133024.97 | Z36: =_xlfn.XLOOKUP(B36,Feuil4!A:A,Feuil4!C:C) -> 24
A37: 2022 | B37: Switzerland | C37: 507.99059 | D37: 502.52324 | E37: 483.33173 | F37: 54.882829 | G37: -0.26478094 | H37: — | I37: — | J37: -0.13 | K37: 4.5518765 | L37: — | M37: — | N37: 162 | O37: 12 | P37: 0.82 | Q37: 0.35725157 | R37: — | S37: 0.16916674 | T37: 33.8 | U37: Europe | V37: -10.881313 | W37: -23.8 | X37: 77120.555 | Z37: =_xlfn.XLOOKUP(B37,Feuil4!A:A,Feuil4!C:C) -> 6
A38: 2022 | B38: Türkiye | C38: 453.15177 | D38: 475.9378 | E38: 456.08404 | F38: 38.33912 | G38: -0.20232522 | H38: — | I38: — | J38: -0.2403495 | K38: 5.635185 | L38: — | M38: — | N38: 236.72229 | O38: 14.102176 | P38: 0.86 | Q38: -0.30048131 | R38: — | S38: -1.185443 | T38: 44.5 | U38: Middle East | V38: -5.7430506 | W38: -24.8 | X38: 30444.388 | Y38: 46708.92 | Z38: =_xlfn.XLOOKUP(B38,Feuil4!A:A,Feuil4!C:C) -> 49
A39: 2022 | B39: United Kingdom | C39: 488.97509 | D39: 499.67021 | E39: 494.40463 | F39: 56.6 | G39: 0 | H39: — | I39: — | J39: 0.26 | K39: 5 | L39: — | M39: — | N39: 192 | O39: 16 | P39: 0.94 | Q39: -0.21 | R39: — | S39: 0.14 | T39: 0 | U39: Europe | V39: -14.369842 | W39: -16.5 | X39: 50809.569 | Y39: 123983.36 | Z39: =_xlfn.XLOOKUP(B39,Feuil4!A:A,Feuil4!C:C) -> 27
A40: 2022 | B40: United States | C40: 464.88804 | D40: 499.41406 | E40: 503.93757 | F40: 55.072901 | G40: -0.29922505 | H40: 0.068709948 | I40: — | J40: 0.25335469 | K40: 3.6350664 | L40: — | M40: — | N40: 371 | O40: 16 | P40: 0.9 | Q40: -0.26195709 | R40: — | S40: 0.056162867 | T40: 41.7 | U40: North America
...

Sheet Feuil2
A1: Jurisdiction | B1: France
A3: Year/Study | B3: Somme de access to money Average | C3: Somme de status of parents (hisei) Average
A4: 2000 | B4: 0 | C4: 48.265041
A5: 2003 | B5: 0 | C5: 48.65971
A6: 2006 | B6: 0 | C6: 48.637808
A7: 2009 | B7: 0 | C7: 46.906423
A8: 2012 | B8: 0 | C8: 51.837689
A9: 2015 | B9: 0 | C9: 51.308749
A10: 2018 | B10: 0 | C10: 51.481305
A11: 2022 | B11: 0 | C11: 53.075124
A12: Total général | B12: 0 | C12: 400.17185

Sheet Infos
A1: Averages for age 15 years index for highest occupational status of parents (hisei) which corresponds to the higher international socio-economic index occupational status (isei) score of either parent or to the only available parent’s isei score. for additional details, see glossary in help guide., by All students [TOTAL] and jurisdiction: 2022, 2018, 2015, 2012, 2009, 2006, 2003, and 2000
A2: Averages for age 15 years student's experience of being bullied (wle), by All students [TOTAL] and jurisdiction: 2022, 2018, 2015, 2012, 2009, 2006, 2003, and 2000
A3: Averages for age 15 years access to money and financial products, sources of money (wle), by All students [TOTAL] and jurisdiction: 2022, 2018, 2015, 2012, 2009, 2006, 2003, and 2000
A4: Averages for age 15 years index of parental/guardian current support for learning at home (wle). for more information, see glossary in help guide., by All students [TOTAL] and jurisdiction: 2022, 2018, 2015, 2012, 2009, 2006, 2003, and 2000
A5: Averages for age 15 years index teacher support in mathematics lessons was derived from students' reports on the frequency with which teachers support learning in mathematics class (teachsup). for additional details, see glossary in help guide., by All students [TOTAL] and jurisdiction: 2022, 2018, 2015, 2012, 2009, 2006, 2003, and 2000
A6: Averages for age 15 years in the last full week you were in school, how many [class periods] did you spend in [mathematics] [in total]?, by All students [TOTAL] and jurisdiction: 2022, 2018, 2015, 2012, 2009, 2006, 2003, and 2000
A7: Averages for age 15 years in the last full week you were in school, how many [class periods] did you spend in [science] [in total]?, by All students [TOTAL] and jurisdiction: 2022, 2018, 2015, 2012, 2009, 2006, 2003, and 2000
A8: Averages for age 15 years in the last full week you were in school, how many [class periods] did you spend in [test language]?, by All students [TOTAL] and jurisdiction: 2022, 2018, 2015, 2012, 2009, 2006, 2003, and 2000
A9: Averages for age 15 years at your school, what is the total number of students in the [national modal grade for 15-year-olds: 10th grade in U.S.]? for more information about national modal grade, see glossary in help guide., by All students [TOTAL] and jurisdiction: 2022, 2018, 2015, 2012, 2009, 2006, 2003, and 2000
A10: Averages for age 15 years student-teacher ratio. for more information, see glossary in help guide., by All students [TOTAL] and jurisdiction: 2022, 2018, 2015, 2012, 2009, 2006, 2003, and 2000
A11: Averages for age 15 years index proportion of all teachers fully certified. for more information, see glossary in help guide., by All students [TOTAL] and jurisdiction: 2022, 2018, 2015, 2012, 2009, 2006, 2003, and 2000
A12: Averages for age 15 years index of sense of belonging to school (wle). for more information, see glossary in help guide., by All students [TOTAL] and jurisdiction: 2022, 2018, 2015, 2012, 2009, 2006, 2003, and 2000
... A15: Averages for age 15 years index of economic, social and cultural status (2022), by All students [TOTAL] and jurisdiction: 2022, 2018, 2015, 2012, 2009, 2006, 2003, and 2000

Sheet NOMENCLATURE
A1: Country | B1: Country2 | C1: Region
A2: France | B2: France | C2: Europe
A3: Allemagne | B3: Germany | C3: Europe
A4: États-Unis | B4: United States | C4: North America
A5: Royaume-Uni | B5: United Kingdom | C5: Europe
A6: Italie | B6: Italy | C6: Europe
A7: Espagne | B7: Spain | C7: Europe
A8: Portugal | B8: Portugal | C8: Europe
A9: Suisse | B9: Switzerland | C9: Europe
A10: Belgique | B10: Belgium | C10: Europe
A11: Pays-Bas | B11: Netherlands | C11: Europe
A12: Autriche | B12: Austria | C12: Europe
... A39: Costa Rica | B39: Costa Rica | C39: North America

Sheet Feuil6
A1: Jurisdiction | B1: France
A3: Étiquettes de lignes | B3: Somme de Mathematics scale Average | C3: Somme de reading scale Average | D3: Somme de science scale Average | E3: Somme de GINI INDICATOR
A4: 2006 | B4: 495.53833 | C4: 487.70625 | D4: 495.21984 | E4: 29.7
A5: 2009 | B5: 496.78231 | C5: 495.61654 | D5: 498.22689 | E5: 32.7
A6: 2012 | B6: 494.98467 | C6: 505.48148 | D6: 498.9709 | E6: 33.1
A7: 2015 | B7: 492.9204 | C7: 499.30614 | D7: 494.9776 | E7: 32.7
A8: 2018 | B8: 495.40758 | C8: 492.60648 | D8: 492.97707 | E8: 32.4
A9: 2022 | B9: 473.94442 | C9: 473.85216 | D9: 487.22528 | E9: 31.2
A10: Total général | B10: 2949.5777 | C10: 2954.5691 | D10: 2967.5976 | E10: 191.8
A41: Jurisdiction | B41: France
A43: Étiquettes de lignes | B43: Somme de Mathematics scale Average | C43: Somme de reading scale Average | D43: Somme de science scale Average | E43: Somme de GINI INDICATOR
A44: 2006 | B44: 495.53833 | C44: 487.70625 | D44: 495.21984 | E44: 29.7
A45: 2009 | B45: 496.78231 | C45: 495.61654 | D45: 498.22689 | E45: 32.7
A46: 2012 | B46: 494.98467 | C46: 505.48148 | D46: 498.9709 | E46: 33.1
A47: 2015 | B47: 492.9204 | C47: 499.30614 | D47: 494.9776 | E47: 32.7
A48: 2018 | B48: 495.40758 | C48: 492.60648 | D48: 492.97707 | E48: 32.4
A49: 2022 | B49: 473.94442 | C49: 473.85216 | D49: 487.22528 | E49: 31.2
A50: Total général | B50: 2949.5777 | C50: 2954.5691 | D50: 2967.5976 | E50: 191.8

Sheet >GINI EXPORT
A1: JURIDICTION | B1: Country Name | C1: 2000 | D1: 2003 | E1: 2006 | F1: 2009 | G1: 2012 | H1: 2015 | I1: 2018 | J1: 2022
A2: Australia | B2: Australie | D2: 33.5 | I2: 34.3
A3: Austria | B3: Autriche | C3: 29 | D3: 29.5 | E3: 29.6 | F3: 31.5 | G3: 30.5 | H3: 30.5 | I3: 30.8 | J3: 30.9
A4: Belgium | B4: Belgique | C4: 33.1 | D4: 28.1 | E4: 28.1 | F4: 28.6 | G4: 27.5 | H4: 27.7 | I4: 27.2 | J4: 26.4
A5: Canada | B5: Canada | C5: 33.4 | D5: 33.8 | E5: 34.1 | F5: 34 | G5: 33.5 | H5: 33.7 | I5: 32.5
A6: Switzerland | B6: Suisse | C6: 33.4 | E6: 33.9 | F6: 32.9 | G6: 31.6 | H6: 32.3 | I6: 33.1 | J6: 33.8
A7: Chile | B7: Chili | C7: 52.8 | D7: 51.5 | E7: 47.7 | F7: 47.4 | H7: 45.3 | J7: 43
A8: Czech Republic | B8: République tchèque | E8: 26.7 | F8: 26.2 | G8: 26.1 | H8: 25.9 | I8: 25 | J8: 25.9
A9: Germany | B9: Allemagne | C9: 28.9 | D9: 29.8 | E9: 31 | F9: 30.5 | G9: 31.1 | H9: 31.7 | I9: 31.9
A10: Denmark | B10: Danemark | C10: 23.8 | D10: 25.6 | E10: 25.9 | F10: 26.7 | G10: 27.8 | H10: 28.2 | I10: 28.2 | J10: 29.3
A11: Spain | B11: Espagne | C11: 34.1 | D11: 31.8 | E11: 33.5 | F11: 34.9 | G11: 35.4 | H11: 36.2 | I11: 34.7 | J11: 33.6
A12: Estonia | B12: Estonie | C12: 35.8 | D12: 37.2 | E12: 33.7 | F12: 31.4 | G12: 32.9 | H12: 32.7 | I12: 30.3 | J12: 32.3
A13: Finland | B13: Finlande | C13: 27.2 | D13: 27.7 | E13: 28 | F13: 27.5 | G13: 27.1 | H13: 27.1 | I13: 27.3 | J13: 27.9
A14: France | B14: France | C14: 32.6 | D14: 31.4 | E14: 29.7 | F14: 32.7 | G14: 33.1 | H14: 32.7 | I14: 32.4 | J14: 31.2
A15: United Kingdom | B15: Royaume-Uni | C15: 38.8 | D15: 34.9 | E15: 35.9 | F15: 35.1 | G15: 33.1 | H15: 33.3 | I15: 33.7
A16: Greece | B16: Grèce | C16: 34.4 | D16: 32.8 | E16: 35.1 | F16: 33.6 | G16: 36.3 | H16: 36 | I16: 32.9 | J16: 33.4
A17: Hungary | B17: Hongrie | C17: 27.2 | D17: 30.9 | E17: 28.3 | F17: 27 | G17: 30.8 | H17: 30.4
A18: Ireland | B18: Irlande | C18: 33 | D18: 32.9 | E18: 32.7 | F18: 32.7 | G18: 33.2 | H18: 31.8 | I18: 30.6 | J18: 29.9
A19: Iceland | B19: Islande | D19: 26.8 | E19: 30.2 | F19: 28.7 | G19: 26.8 | H19: 26.8 | I19: 26.6
A20: Israel | B20: Israël | D20: 40.7 | E20: 41.6 | F20: 42.6 | G20: 41.3 | H20: 39.7 | I20: 38.6
A21: Italy | B21: Italie | C21: 35.2 | D21: 34.9 | E21: 33.7 | F21: 33.8 | G21: 35.2 | H21: 35.4 | I21: 35.2 | J21: 33.7
A22: Japan | B22: Japon | F22: 33 | G22: 32.5 | H22: 30.7 | I22: 32.9
A23: Lithuania | B23: Lituanie | C23: 31.7 | D23: 35.5 | E23: 34.4 | F23: 37.2 | G23: 35.1 | H23: 37.4 | I23: 35.7 | J23: 36.6
A24: Luxembourg | B24: Luxembourg | C24: 30.1 | D24: 30.2 | E24: 30.9 | F24: 31.2 | G24: 34.3 | H24: 32.9 | I24: 35.4 | J24: 34.1
A25: Latvia | B25: Lettonie | D25: 36.5 | E25: 35.6 | F25: 35.9 | G25: 35.2 | H25: 34.2 | I25: 35.1 | J25: 33.7
A26: Mexico | B26: Mexique | C26: 53.4 | E26: 49.7 | G26: 49.6 | I26: 46 | J26: 43.5
A27: Netherlands | B27: Pays-Bas | E27: 30 | F27: 27.9 | G27: 27.6 | H27: 28.2 | I27: 28.1
A28: Norway | B28: Norvège | C28: 27.4 | D28: 27.6 | E28: 26.4 | F28: 26.2 | G28: 25.7 | H28: 27.5 | I28: 27.6 | J28: 26.9
A29: New Zealand | B29: Nouvelle-Zélande
A30: Poland | B30: Pologne | C30: 33 | D30: 34.9 | E30: 34.7 | F30: 33.4 | G30: 33 | H30: 31.8 | I30: 30.2 | J30: 28.9
A31: Portugal | B31: Portugal | D31: 38.8 | E31: 38.1 | F31: 34.9 | G31: 36 | H31: 35.5 | I31: 33.5 | J31: 36.3
A32: Slovenia | B32: Slovénie | D32: 30.9 | E32: 24.4 | F32: 24.8 | G32: 25.6 | H32: 25.4 | I32: 24.6 | J32: 24.3
A33: Sweden | B33: Suède | C33: 27 | D33: 25.3 | E33: 26.4 | F33: 27.3 | G33: 27.6 | H33: 29.2 | I33: 30 | J33: 31.6
A34: Türkiye | B34: Turquie | D34: 42.2 | E34: 39.6 | F34: 39 | G34: 40.2 | H34: 42.9 | I34: 42.4 | J34: 44.5
A35: United States | B35: États-Unis | C35: 40.1 | D35: 40.8 | E35: 41.7 | F35: 40.8 | G35: 41.2 | H35: 41.5 | I35: 41.8 | J35: 41.7

Sheet Feuil3
A1: FEATURES | B1: CORRELATION | C1: ABS CORR
A2: parent attitudes toward mathematics Average | B2: -0.84999716 | C2: =ABS(B2) -> 0.84999716
A3: economic. social and cultural status Average | B3: 0.67185956 | C3: =ABS(B3) -> 0.67185956
A4: teachers fully certified Average | B4: 0.6234152 | C4: =ABS(B4) -> 0.6234152
A5: access to money Average | B5: 0.51886171 | C5: =ABS(B5) -> 0.51886171
A6: status of parents (hisei) Average | B6: 0.51759621 | C6: =ABS(B6) -> 0.51759621
A7: student-teacher ratio Average | B7: -0.496253 | C7: =ABS(B7) -> 0.496253
A8: index teacher support in mathematics lessons Average | B8: -0.4780662 | C8: =ABS(B8) -> 0.4780662
A9: current support for learning at home Average | B9: -0.45592355 | C9: =ABS(B9) -> 0.45592355
A10: Class Period Mathematics Average | B10: -0.26705142 | C10: =ABS(B10) -> 0.26705142
A11: Class Period Science Average | B11: -0.25085853 | C11: =ABS(B11) -> 0.25085853
A12: Class Periods Language Average | B12: -0.11799182 | C12: =ABS(B12) -> 0.11799182
A13: sense of belonging to school Average | B13: 0.076054313 | C13: =ABS(B13) -> 0.076054313
... A15: experience of being bullied Average | B15: 0.030548541 | C15: =ABS(B15) -> 0.030548541

Sheet Feuil1
A1: Maths | B1: Gender gap (boys - girls) | D1: Readings | E1: Gender gap (boys - girls) | I1: GDP | L1: Mathematics performance | M1: Expenditure
A2: Italy | B2: 21.06222 | D2: Costa Rica | E2: -2.6 | H2: Serbia | I2: 21641.851 | K2: Serbia | L2: 439.87667 | M2: 45963.431
A3: Austria | B3: 19.055576 | D3: Chile | E3: -6.6 | H3: Netherlands | I3: 63741.704 | K3: Netherlands | L3: 492.67564 | M3: 119584.16
A4: Chile | B4: 16.286793 | D4: Mexico | E4: -7.8 | H4: Kosovo | I4: 13055.901 | K4: Moldova | L4: 414.19806 | M4: 35686.341
A5: Peru | B5: 15.167873 | D5: Peru | E5: -8.1 | H5: Moldova | I5: 15390.466 | K5: Palestinian Authority | L5: 365.74668 | M5: 30891.362
A6: Costa Rica | B6: 15.16378 | D6: Guatemala | E6: -9.5 | H6: Saudi Arabia | I6: 48710.948 | K6: Germany | L6: 474.82645 | M6: 121061.54
A7: Hungary | B7: 14.857639 | D7: Colombia | E7: -11.6 | H7: Palestinian Authority | I7: 6199.451 | K7: Finland | L7: 484.13923 | M7: 126777.01
A8: United Kingdom | B8: 14.369842 | D8: El Salvador | E8: -13.2 | H8: Germany | I8: 58276.015 | K8: Brunei Darussalam | L8: 442.0931 | M8: 207324.23
A9: United States | B9: 13.269493 | D9: Argentina | E9: -14.2 | H9: Finland | I9: 55203.328 | K9: Hong Kong (China) | L9: 540.3518 | M9: 124555.74
A10: Ireland | B10: 12.725275 | D10: Uruguay | E10: -15.1 | H10: Brunei Darussalam | I10: 66055.248 | K10: Indonesia | L10: 365.52525 | M10: 19716.433
A11: Guatemala | B11: 12.487024 | D11: United Kingdom | E11: -16.5 | H11: Hong Kong (China) | I11: 65891.695 | K11: United States | L11: 464.88804 | M11: 143383.17
A12: Canada | B12: 12.325277 | D12: Japan | E12: -16.6 | H12: Indonesia | I12: 13027.301 | K12: Slovak Republic | L12: 463.99462 | M12: 75299.806
A13: Singapore | B13: 12.105377 | D13: Hungary | E13: -16.9 | H13: United States | I13: 69287.537 | K13: El Salvador | L13: 343.4691 | M13: 15097.122
... A73: Philippines | B73: -14.181675 | D73: United Arab Emirates | E73: -44.5 | H73: Estonia | I73: 42380.968 | K73: OECD average | L73: 472.35765 | M73: 102611.92
A74: Jordan | B74: -14.983643 | D74: Finland | E74: -44.7 | H74: Bulgaria | I74: 28105.969
A75: Albania | B75: -19.052195 | D75: Jordan | E75: -46.1 | H75: Malta | I75: 48894.342
B76: 0 | E76: 0 | H76: Portugal | I76: 36037.958
A77: Macao (China) | B77: 15.467555 | D77: Macao (China) | E77: -14.4 | H77: Canada | I77: 52789.675
A78: Ukrainian regions (18 of 27) | B78: 9.9234114 | D78: Hong Kong (China)* | E78: -22.9 | H78: Jordan | I78: 10132.504
A79: Hong Kong (China)* | B79: 8.7238188 | D79: Ukrainian regions (18 of 27) | E79: -23.2 | H79: Montenegro | I79: 23434.533
A80: Chinese Taipei | B80: 5.6302247 | D80: Kosovo | E80: -25 | H80: France | I80: 50996.437
A81: Kosovo | B81: 0.39665383 | D81: Chinese Taipei | E81: -26.9 | H81: Spain | I81: 40591.759
A82: Baku (Azerbaijan) | B82: -7.0537701 | D82: Baku (Azerbaijan) | E82: -37.5 | H82: Korea | I82: 46888.791
A83: Palestinian Authority | B83: -15.561196 | D83: Palestinian Authority | E83: -49.4 | H83: OECD average | I83: 48388.078

Sheet Feuil4
A1: Country | B1: ISO | C1: Duration of FULL and PARTIAL school closures (in weeks) | D1: Duration of FULL closures (in weeks) | E1: Duration of PARTIAL closures (in weeks) | F1: Duration of FULL closures from Mar-Aug 20 (in weeks) | G1: Duration of FULL closures from Sep 20 - Aug 21 (in weeks) | H1: Duration of FULL closures from Sep 21 - Oct 21 (in weeks) | I1: Duration of PARTIAL closures from Mar-Aug 20 (in weeks) | J1: Duration of PARTIAL closures from Sep 20 - Aug 21 (in weeks) | K1: Duration of PARTIAL closures from Sep 21 - Oct 21 (in weeks)
A2: Afghanistan | B2: AFG | C2: 57 | D2: 35 | E2: 22 | F2: 23 | G2: 9 | H2: 3 | I2: 3 | J2: 9 | K2: 10
A3: Albania | B3: ALB | C3: 29 | D3: 11 | E3: 18 | F3: 8 | G3: 3 | H3: 0 | I3: 5 | J3: 13 | K3: 0
A4: Algeria | B4: DZA | C4: 21 | D4: 19 | E4: 2 | F4: 13 | G4: 6 | H4: 0 | I4: 0 | J4: 2 | K4: 0
A5: Andorra | B5: AND | C5: 16 | D5: 15 | E5: 1 | F5: 15 | G5: 0 | H5: 0 | I5: 0 | J5: 1 | K5: 0
A6: Angola | B6: AGO | C6: 46 | D6: 28 | E6: 18 | F6: 23 | G6: 5 | H6: 0 | I6: 0 | J6: 18 | K6: 0
A7: Anguilla | B7: AIA | C7: 28 | D7: 7 | E7: 21 | F7: 4 | G7: 0 | H7: 3 | I7: 12 | J7: 0 | K7: 9
A8: Antigua and Barbuda | B8: ATG | C8: 65 | D8: 28 | E8: 37 | F8: 16 | G8: 10 | H8: 2 | I8: 0 | J8: 28 | K8: 9
A9: Argentina | B9: ARG | C9: 79 | D9: 22 | E9: 57 | F9: 22 | G9: 0 | H9: 0 | I9: 0 | J9: 44 | K9: 13
A10: Armenia | B10: ARM | C10: 12 | D10: 9 | E10: 3 | F10: 9 | G10: 0 | H10: 0 | I10: 0 | J10: 3 | K10: 0
A11: Aruba | B11: ABW | C11: 13 | D11: 8 | E11: 5 | F11: 8 | G11: 0 | H11: 0 | I11: 0 | J11: 5 | K11: 0
A12: Australia | B12: AUS | C12: 44 | D12: 0 | E12: 44 | F12: 0 | G12: 0 | H12: 0 | I12: 17 | J12: 20 | K12: 7
A13: Austria | B13: AUT | C13: 39 | D13: 15 | E13: 24 | F13: 6 | G13: 9 | H13: 0 | I13: 4 | J13: 19 | K13: 1
... A211: Mauritania | B211: MRT | C211: 23 | D211: 23 | E211: 0 | F211: 18 | G211: 5 | H211: 0 | I211: 0 | J211: 0 | K211: 0
